2022-03-07 16:00:03 WARNING (SyncWorker_0) [homeassistant.loader] We found a custom integration auto_backup which has not been tested by Home Assistant. This component might cause stability problems, be sure to disable it if you experience issues with Home Assistant
2022-03-07 16:00:03 WARNING (SyncWorker_2) [homeassistant.loader] We found a custom integration fontawesome which has not been tested by Home Assistant. This component might cause stability problems, be sure to disable it if you experience issues with Home Assistant
2022-03-07 16:00:03 WARNING (SyncWorker_1) [homeassistant.loader] We found a custom integration thermal_comfort which has not been tested by Home Assistant. This component might cause stability problems, be sure to disable it if you experience issues with Home Assistant
2022-03-07 16:00:03 WARNING (SyncWorker_4) [homeassistant.loader] We found a custom integration hacs which has not been tested by Home Assistant. This component might cause stability problems, be sure to disable it if you experience issues with Home Assistant
2022-03-07 16:00:03 WARNING (SyncWorker_3) [homeassistant.loader] We found a custom integration adaptive_lighting which has not been tested by Home Assistant. This component might cause stability problems, be sure to disable it if you experience issues with Home Assistant
2022-03-07 16:00:17 ERROR (MainThread) [homeassistant.components.zwave_js] Discovery for value Value(value_id='4-50-0-value-328193') on device 'Dehumidifier' (Node(node_id=4)) will be skipped: Value Value(value_id='4-50-0-value-328193') has unknown data in the following location: metadata.cc_specific.scale. A reinterview of node Node(node_id=4) may correct this issue, but if it doesn't, please report this issue as it may be caused by either an upstream issue with the driver or missing support for this data in the library
2022-03-07 16:00:17 ERROR (MainThread) [homeassistant.components.zwave_js] Discovery for value Value(value_id='4-50-0-value-513') on device 'Dehumidifier' (Node(node_id=4)) will be skipped: Value Value(value_id='4-50-0-value-513') has unknown data in the following location: metadata.cc_specific.meterType. A reinterview of node Node(node_id=4) may correct this issue, but if it doesn't, please report this issue as it may be caused by either an upstream issue with the driver or missing support for this data in the library
2022-03-07 16:00:47 WARNING (SyncWorker_1) [pychromecast.dial] Failed to determine cast type
2022-03-07 16:32:21 WARNING (SyncWorker_6) [homeassistant.loader] We found a custom integration mjpeg_timelapse which has not been tested by Home Assistant. This component might cause stability problems, be sure to disable it if you experience issues with Home Assistant
2022-03-07 16:32:21 WARNING (SyncWorker_0) [homeassistant.loader] We found a custom integration auto_backup which has not been tested by Home Assistant. This component might cause stability problems, be sure to disable it if you experience issues with Home Assistant
2022-03-07 16:32:21 WARNING (SyncWorker_6) [homeassistant.loader] We found a custom integration hacs which has not been tested by Home Assistant. This component might cause stability problems, be sure to disable it if you experience issues with Home Assistant
2022-03-07 16:32:21 WARNING (SyncWorker_2) [homeassistant.loader] We found a custom integration adaptive_lighting which has not been tested by Home Assistant. This component might cause stability problems, be sure to disable it if you experience issues with Home Assistant
2022-03-07 16:32:21 WARNING (SyncWorker_8) [homeassistant.loader] We found a custom integration fontawesome which has not been tested by Home Assistant. This component might cause stability problems, be sure to disable it if you experience issues with Home Assistant
2022-03-07 16:32:21 WARNING (SyncWorker_5) [homeassistant.loader] We found a custom integration thermal_comfort which has not been tested by Home Assistant. This component might cause stability problems, be sure to disable it if you experience issues with Home Assistant
2022-03-07 16:50:36 ERROR (stream_worker) [homeassistant.components.stream.stream.camera.living_room] Error from stream worker: Error opening stream (HTTP_NOT_FOUND, Server returned 404 Not Found) rtsps://stream-us1-foxtrot.dropcam.com:443/sdm_live_stream/CiUA2vuxryhoS3X1VTPplWeHSFcse3puHdnjSdkJI1E5stF9wBJEEnEA9W2XOH3widuHjfUd8lrs7L8HfeCDNfkhq9GTMS2FETGGbSAIsiFMK9TXdpUvyWKhFsKLAY6M_jtgdSGhxmPppJRImCOyHetSSobc12n2W0vBHQwC7S3m2JzldkHvUMU6khf1Hu3FVQwZ5bZ2-SOyyQ?auth=****
2022-03-07 16:55:06 ERROR (stream_worker) [homeassistant.components.stream.stream.camera.living_room] Error from stream worker: Error opening stream (HTTP_NOT_FOUND, Server returned 404 Not Found) rtsps://stream-us1-foxtrot.dropcam.com:443/sdm_live_stream/CiUA2vuxryhoS3X1VTPplWeHSFcse3puHdnjSdkJI1E5stF9wBJEEnEA9W2XOH3widuHjfUd8lrs7L8HfeCDNfkhq9GTMS2FETGGbSAIsiFMK9TXdpUvyWKhFsKLAY6M_jtgdSGhxmPppJRImCOyHetSSobc12n2W0vBHQwC7S3m2JzldkHvUMU6khf1Hu3FVQwZ5bZ2-SOyyQ?auth=****
2022-03-07 16:59:41 ERROR (stream_worker) [homeassistant.components.stream.stream.camera.living_room] Error from stream worker: Error opening stream (HTTP_NOT_FOUND, Server returned 404 Not Found) rtsps://stream-us1-foxtrot.dropcam.com:443/sdm_live_stream/CiUA2vuxryhoS3X1VTPplWeHSFcse3puHdnjSdkJI1E5stF9wBJEEnEA9W2XOH3widuHjfUd8lrs7L8HfeCDNfkhq9GTMS2FETGGbSAIsiFMK9TXdpUvyWKhFsKLAY6M_jtgdSGhxmPppJRImCOyHetSSobc12n2W0vBHQwC7S3m2JzldkHvUMU6khf1Hu3FVQwZ5bZ2-SOyyQ?auth=****
2022-03-07 17:01:06 ERROR (stream_worker) [homeassistant.components.stream.stream.camera.living_room] Error from stream worker: Stream ended; no additional packets
2022-03-07 17:04:07 ERROR (stream_worker) [homeassistant.components.stream.stream.camera.living_room] Error from stream worker: Error opening stream (HTTP_NOT_FOUND, Server returned 404 Not Found) rtsps://stream-us1-foxtrot.dropcam.com:443/sdm_live_stream/CiUA2vuxryhoS3X1VTPplWeHSFcse3puHdnjSdkJI1E5stF9wBJEEnEA9W2XOH3widuHjfUd8lrs7L8HfeCDNfkhq9GTMS2FETGGbSAIsiFMK9TXdpUvyWKhFsKLAY6M_jtgdSGhxmPppJRImCOyHetSSobc12n2W0vBHQwC7S3m2JzldkHvUMU6khf1Hu3FVQwZ5bZ2-SOyyQ?auth=****
2022-03-07 17:06:07 ERROR (stream_worker) [homeassistant.components.stream.stream.camera.living_room] Error from stream worker: Stream ended; no additional packets
2022-03-07 17:08:17 ERROR (stream_worker) [homeassistant.components.stream.stream.camera.living_room] Error from stream worker: Stream ended; no additional packets
2022-03-07 18:06:05 ERROR (MainThread) [homeassistant.core] Error executing service: <ServiceCall switch.turn_off (c:71e8967107a252965869eb4a76c7cea2): entity_id=['switch.living_room_smart_tv']>
Traceback (most recent call last):
  File "/usr/src/homeassistant/homeassistant/core.py", line 1654, in catch_exceptions
    await coro_or_task
  File "/usr/src/homeassistant/homeassistant/core.py", line 1673, in _execute_service
    await cast(Callable[[ServiceCall], Awaitable[None]], handler.job.target)(
  File "/usr/src/homeassistant/homeassistant/helpers/entity_component.py", line 204, in handle_service
    await self.hass.helpers.service.entity_service_call(
  File "/usr/src/homeassistant/homeassistant/helpers/service.py", line 668, in entity_service_call
    future.result()  # pop exception if have
  File "/usr/src/homeassistant/homeassistant/helpers/entity.py", line 931, in async_request_call
    await coro
  File "/usr/src/homeassistant/homeassistant/helpers/service.py", line 705, in _handle_entity_call
    await result
  File "/usr/src/homeassistant/homeassistant/components/smartthings/switch.py", line 46, in async_turn_off
    await self._device.switch_off(set_status=True)
  File "/usr/local/lib/python3.9/site-packages/pysmartthings/device.py", line 1013, in switch_off
    result = await self.command(component_id, Capability.switch, Command.off)
  File "/usr/local/lib/python3.9/site-packages/pysmartthings/device.py", line 825, in command
    response = await self._api.post_device_command(
  File "/usr/local/lib/python3.9/site-packages/pysmartthings/api.py", line 147, in post_device_command
    return await self.post(API_DEVICE_COMMAND.format(device_id=device_id), data)
  File "/usr/local/lib/python3.9/site-packages/pysmartthings/api.py", line 395, in post
    return await self.request("post", self._api_base + resource, data=data)
  File "/usr/local/lib/python3.9/site-packages/pysmartthings/api.py", line 376, in request
    resp.raise_for_status()
  File "/usr/local/lib/python3.9/site-packages/aiohttp/client_reqrep.py", line 1004, in raise_for_status
    raise ClientResponseError(
aiohttp.client_exceptions.ClientResponseError: 409, message='Conflict', url=URL('https://api.smartthings.com/v1/devices/650f9917-534d-4698-8409-29cc0a350971/commands')
2022-03-07 18:21:25 ERROR (MainThread) [pylitterbot.account] Unable to retrieve your robots
2022-03-07 18:34:32 WARNING (MainThread) [homeassistant.helpers.service] Unable to find referenced entities switch.roof_christmas_lights1
2022-03-07 19:03:40 WARNING (MainThread) [homeassistant.components.media_player] Updating dlna_dmr media_player took longer than the scheduled update interval 0:00:10
2022-03-07 19:03:40 WARNING (MainThread) [homeassistant.helpers.entity] Update of media_player.living_room_receiver_3 is taking over 10 seconds
2022-03-07 19:34:20 WARNING (MainThread) [homeassistant.components.media_player] Updating dlna_dmr media_player took longer than the scheduled update interval 0:00:10
2022-03-07 19:34:20 WARNING (MainThread) [homeassistant.helpers.entity] Update of media_player.living_room_receiver_3 is taking over 10 seconds
2022-03-07 19:41:20 WARNING (MainThread) [homeassistant.components.media_player] Updating dlna_dmr media_player took longer than the scheduled update interval 0:00:10
2022-03-07 19:41:20 WARNING (MainThread) [homeassistant.helpers.entity] Update of media_player.living_room_receiver_3 is taking over 10 seconds
2022-03-07 19:48:20 WARNING (MainThread) [homeassistant.components.media_player] Updating dlna_dmr media_player took longer than the scheduled update interval 0:00:10
2022-03-07 19:48:20 WARNING (MainThread) [homeassistant.helpers.entity] Update of media_player.living_room_receiver_3 is taking over 10 seconds
2022-03-07 20:09:30 WARNING (MainThread) [homeassistant.components.media_player] Updating dlna_dmr media_player took longer than the scheduled update interval 0:00:10
2022-03-07 20:09:30 WARNING (MainThread) [homeassistant.helpers.entity] Update of media_player.living_room_receiver_3 is taking over 10 seconds
2022-03-07 21:27:02 ERROR (MainThread) [pylitterbot.account] Unable to retrieve your robots
2022-03-07 22:59:40 ERROR (MainThread) [homeassistant.core] Error executing service: <ServiceCall switch.turn_off (c:1ab8d9d00d8ca2987697fdb0235c97a9): entity_id=['switch.living_room_smart_tv']>
Traceback (most recent call last):
  File "/usr/src/homeassistant/homeassistant/core.py", line 1654, in catch_exceptions
    await coro_or_task
  File "/usr/src/homeassistant/homeassistant/core.py", line 1673, in _execute_service
    await cast(Callable[[ServiceCall], Awaitable[None]], handler.job.target)(
  File "/usr/src/homeassistant/homeassistant/helpers/entity_component.py", line 204, in handle_service
    await self.hass.helpers.service.entity_service_call(
  File "/usr/src/homeassistant/homeassistant/helpers/service.py", line 668, in entity_service_call
    future.result()  # pop exception if have
  File "/usr/src/homeassistant/homeassistant/helpers/entity.py", line 931, in async_request_call
    await coro
  File "/usr/src/homeassistant/homeassistant/helpers/service.py", line 705, in _handle_entity_call
    await result
  File "/usr/src/homeassistant/homeassistant/components/smartthings/switch.py", line 46, in async_turn_off
    await self._device.switch_off(set_status=True)
  File "/usr/local/lib/python3.9/site-packages/pysmartthings/device.py", line 1013, in switch_off
    result = await self.command(component_id, Capability.switch, Command.off)
  File "/usr/local/lib/python3.9/site-packages/pysmartthings/device.py", line 825, in command
    response = await self._api.post_device_command(
  File "/usr/local/lib/python3.9/site-packages/pysmartthings/api.py", line 147, in post_device_command
    return await self.post(API_DEVICE_COMMAND.format(device_id=device_id), data)
  File "/usr/local/lib/python3.9/site-packages/pysmartthings/api.py", line 395, in post
    return await self.request("post", self._api_base + resource, data=data)
  File "/usr/local/lib/python3.9/site-packages/pysmartthings/api.py", line 376, in request
    resp.raise_for_status()
  File "/usr/local/lib/python3.9/site-packages/aiohttp/client_reqrep.py", line 1004, in raise_for_status
    raise ClientResponseError(
aiohttp.client_exceptions.ClientResponseError: 409, message='Conflict', url=URL('https://api.smartthings.com/v1/devices/650f9917-534d-4698-8409-29cc0a350971/commands')
2022-03-08 02:01:09 ERROR (Thread-13) [pychromecast.socket_client] [Bedroom Hub(6.6.6.199):8009] Error reading from socket.
2022-03-08 02:01:09 WARNING (Thread-13) [pychromecast.socket_client] [Bedroom Hub(6.6.6.199):8009] Error communicating with socket, resetting connection
2022-03-08 02:01:09 ERROR (Thread-13) [pychromecast.socket_client] [Bedroom Hub(6.6.6.199):8009] Failed to connect to service ServiceInfo(type='host', data=('6.6.6.199', 8009)), retrying in 5.0s
2022-03-08 02:22:51 WARNING (Thread-6) [pychromecast.socket_client] [Living Room TV(6.6.6.20):8009] Heartbeat timeout, resetting connection
2022-03-08 02:23:06 ERROR (Thread-6) [pychromecast.socket_client] [Living Room TV(6.6.6.20):8009] Failed to connect to service ServiceInfo(type='host', data=('6.6.6.20', 8009)), retrying in 5.0s
2022-03-08 02:48:58 ERROR (Thread-8) [pychromecast.socket_client] [Kitchen Hub(6.6.6.142):8009] Error reading from socket.
2022-03-08 02:48:58 WARNING (Thread-8) [pychromecast.socket_client] [Kitchen Hub(6.6.6.142):8009] Error communicating with socket, resetting connection
2022-03-08 02:48:58 ERROR (Thread-8) [pychromecast.socket_client] [Kitchen Hub(6.6.6.142):8009] Failed to connect to service ServiceInfo(type='host', data=('6.6.6.142', 8009)), retrying in 5.0s
2022-03-08 03:13:19 WARNING (Thread-15) [pychromecast.socket_client] [Living Room Mini(6.6.6.79):8009] Heartbeat timeout, resetting connection
2022-03-08 03:13:35 ERROR (Thread-15) [pychromecast.socket_client] [Living Room Mini(6.6.6.79):8009] Failed to connect to service ServiceInfo(type='host', data=('6.6.6.79', 8009)), retrying in 5.0s
2022-03-08 03:53:58 WARNING (Thread-10) [pychromecast.socket_client] [Library TV(6.6.6.21):8009] Heartbeat timeout, resetting connection
2022-03-08 03:54:13 ERROR (Thread-10) [pychromecast.socket_client] [Library TV(6.6.6.21):8009] Failed to connect to service ServiceInfo(type='host', data=('6.6.6.21', 8009)), retrying in 5.0s
2022-03-08 04:03:08 WARNING (Thread-14) [pychromecast.socket_client] [Library Mini(6.6.6.179):8009] Heartbeat timeout, resetting connection
2022-03-08 04:03:23 ERROR (Thread-14) [pychromecast.socket_client] [Library Mini(6.6.6.179):8009] Failed to connect to service ServiceInfo(type='host', data=('6.6.6.179', 8009)), retrying in 5.0s
2022-03-08 04:04:03 ERROR (Thread-16) [pychromecast.socket_client] [Home Speakers(6.6.6.93):32171] Error reading from socket.
2022-03-08 04:04:03 WARNING (Thread-16) [pychromecast.socket_client] [Home Speakers(6.6.6.93):32171] Error communicating with socket, resetting connection
2022-03-08 04:04:03 ERROR (Thread-16) [pychromecast.socket_client] [Home Speakers(6.6.6.93):32171] Failed to connect to service ServiceInfo(type='host', data=('6.6.6.93', 32171)), retrying in 5.0s
2022-03-08 04:04:28 WARNING (Thread-17) [pychromecast.socket_client] [Living Room speaker(6.6.6.93):8009] Heartbeat timeout, resetting connection
2022-03-08 04:04:43 ERROR (Thread-17) [pychromecast.socket_client] [Living Room speaker(6.6.6.93):8009] Failed to connect to service ServiceInfo(type='host', data=('6.6.6.93', 8009)), retrying in 5.0s
2022-03-08 04:04:48 ERROR (Thread-16) [pychromecast.socket_client] [Home Speakers(6.6.6.79):32171] Error reading from socket.
2022-03-08 04:04:48 WARNING (Thread-16) [pychromecast.socket_client] [Home Speakers(6.6.6.79):32171] Error communicating with socket, resetting connection
2022-03-08 04:04:48 ERROR (Thread-16) [pychromecast.socket_client] [Home Speakers(6.6.6.93):32171] Failed to connect to service ServiceInfo(type='host', data=('6.6.6.93', 32171)), retrying in 5.0s
2022-03-08 06:14:11 ERROR (MainThread) [aiohttp.server] Error handling request
Traceback (most recent call last):
  File "/usr/local/lib/python3.9/site-packages/aiohttp/web_protocol.py", line 435, in _handle_request
    resp = await request_handler(request)
  File "/usr/local/lib/python3.9/site-packages/aiohttp/web_app.py", line 473, in _handle
    match_info = await self._router.resolve(request)
  File "/usr/local/lib/python3.9/site-packages/aiohttp/web_urldispatcher.py", line 1010, in resolve
    match_dict, allowed = await resource.resolve(request)
  File "/usr/src/homeassistant/homeassistant/components/frontend/__init__.py", line 536, in resolve
    and request.url.parts[1] not in self.hass.data[DATA_PANELS]
IndexError: tuple index out of range
2022-03-08 08:00:21 ERROR (Thread-16) [homeassistant.components.cast.media_player] Failed to cast media https://leviathan.network/api/tts_proxy/e67e8b68b05754b339004b1eb6b18fb7cdb66a4b_en-us_826d21f2a0_cloud.mp3?authSig=eyJ0eXAiOiJKV1QiLCJhbGciOiJIUzI1NiJ9.eyJpc3MiOiI3ZWZlZDU4MzNkYzM0NmY3OTgxOWZmYmQ4OWUxOGVjZSIsInBhdGgiOiIvYXBpL3R0c19wcm94eS9lNjdlOGI2OGIwNTc1NGIzMzkwMDRiMWViNmIxOGZiN2NkYjY2YTRiX2VuLXVzXzgyNmQyMWYyYTBfY2xvdWQubXAzIiwiaWF0IjoxNjQ2NzQ0NDE5LCJleHAiOjE2NDY4MzA4MTl9.WpCXZNrI0oYmrCh426z1qGlax-PLY0jtQ6fpRNDuhj8 from internal_url (https://leviathan.network). Please make sure the URL is: Reachable from the cast device and either a publicly resolvable hostname or an IP address
2022-03-08 08:00:28 ERROR (Thread-16) [homeassistant.components.cast.media_player] Failed to cast media https://leviathan.network/api/tts_proxy/4a76de62c0642791488beedb76e79c00dfa31c7e_en-us_826d21f2a0_cloud.mp3?authSig=eyJ0eXAiOiJKV1QiLCJhbGciOiJIUzI1NiJ9.eyJpc3MiOiI3ZWZlZDU4MzNkYzM0NmY3OTgxOWZmYmQ4OWUxOGVjZSIsInBhdGgiOiIvYXBpL3R0c19wcm94eS80YTc2ZGU2MmMwNjQyNzkxNDg4YmVlZGI3NmU3OWMwMGRmYTMxYzdlX2VuLXVzXzgyNmQyMWYyYTBfY2xvdWQubXAzIiwiaWF0IjoxNjQ2NzQ0NDI4LCJleHAiOjE2NDY4MzA4Mjh9.o5oQAtZROOYeMuQxmCfZfDqXxRwmxyrZXuswV1xq_OU from internal_url (https://leviathan.network). Please make sure the URL is: Reachable from the cast device and either a publicly resolvable hostname or an IP address
2022-03-08 08:00:29 ERROR (Thread-16) [homeassistant.components.cast.media_player] Failed to cast media https://leviathan.network/api/tts_proxy/4a76de62c0642791488beedb76e79c00dfa31c7e_en-us_826d21f2a0_cloud.mp3?authSig=eyJ0eXAiOiJKV1QiLCJhbGciOiJIUzI1NiJ9.eyJpc3MiOiI3ZWZlZDU4MzNkYzM0NmY3OTgxOWZmYmQ4OWUxOGVjZSIsInBhdGgiOiIvYXBpL3R0c19wcm94eS80YTc2ZGU2MmMwNjQyNzkxNDg4YmVlZGI3NmU3OWMwMGRmYTMxYzdlX2VuLXVzXzgyNmQyMWYyYTBfY2xvdWQubXAzIiwiaWF0IjoxNjQ2NzQ0NDI4LCJleHAiOjE2NDY4MzA4Mjh9.o5oQAtZROOYeMuQxmCfZfDqXxRwmxyrZXuswV1xq_OU from internal_url (https://leviathan.network). Please make sure the URL is: Reachable from the cast device and either a publicly resolvable hostname or an IP address
2022-03-08 08:02:10 ERROR (MainThread) [homeassistant.core] Error executing service: <ServiceCall switch.turn_off (c:63e8de521dbb270503614a30325178c4): entity_id=['switch.living_room_smart_tv']>
Traceback (most recent call last):
  File "/usr/src/homeassistant/homeassistant/core.py", line 1654, in catch_exceptions
    await coro_or_task
  File "/usr/src/homeassistant/homeassistant/core.py", line 1673, in _execute_service
    await cast(Callable[[ServiceCall], Awaitable[None]], handler.job.target)(
  File "/usr/src/homeassistant/homeassistant/helpers/entity_component.py", line 204, in handle_service
    await self.hass.helpers.service.entity_service_call(
  File "/usr/src/homeassistant/homeassistant/helpers/service.py", line 668, in entity_service_call
    future.result()  # pop exception if have
  File "/usr/src/homeassistant/homeassistant/helpers/entity.py", line 931, in async_request_call
    await coro
  File "/usr/src/homeassistant/homeassistant/helpers/service.py", line 705, in _handle_entity_call
    await result
  File "/usr/src/homeassistant/homeassistant/components/smartthings/switch.py", line 46, in async_turn_off
    await self._device.switch_off(set_status=True)
  File "/usr/local/lib/python3.9/site-packages/pysmartthings/device.py", line 1013, in switch_off
    result = await self.command(component_id, Capability.switch, Command.off)
  File "/usr/local/lib/python3.9/site-packages/pysmartthings/device.py", line 825, in command
    response = await self._api.post_device_command(
  File "/usr/local/lib/python3.9/site-packages/pysmartthings/api.py", line 147, in post_device_command
    return await self.post(API_DEVICE_COMMAND.format(device_id=device_id), data)
  File "/usr/local/lib/python3.9/site-packages/pysmartthings/api.py", line 395, in post
    return await self.request("post", self._api_base + resource, data=data)
  File "/usr/local/lib/python3.9/site-packages/pysmartthings/api.py", line 376, in request
    resp.raise_for_status()
  File "/usr/local/lib/python3.9/site-packages/aiohttp/client_reqrep.py", line 1004, in raise_for_status
    raise ClientResponseError(
aiohttp.client_exceptions.ClientResponseError: 409, message='Conflict', url=URL('https://api.smartthings.com/v1/devices/650f9917-534d-4698-8409-29cc0a350971/commands')
2022-03-08 08:06:28 WARNING (MainThread) [google_nest_sdm.event_media] Failure when pre-fetching event 'AVPHwEvvhbk22dcaXsd62CtfZcvQ3WTowEJdu1ZbS6teL4Tud-D8o7OU6J-mhWQLX9WrXOEOYCksFZFcF_WPyNokIRp7FkU': Error from API: 503: UNAVAILABLE: The camera image is no longer available for download.: Service Unavailable
2022-03-08 08:18:47 ERROR (MainThread) [pylitterbot.account] Unable to retrieve your robots
2022-03-08 08:38:04 ERROR (MainThread) [homeassistant.components.websocket_api.http.connection] [140037327311344] 409, message='Conflict', url=URL('https://api.smartthings.com/v1/devices/650f9917-534d-4698-8409-29cc0a350971/commands')
Traceback (most recent call last):
  File "/usr/src/homeassistant/homeassistant/components/websocket_api/commands.py", line 192, in handle_call_service
    await hass.services.async_call(
  File "/usr/src/homeassistant/homeassistant/core.py", line 1636, in async_call
    task.result()
  File "/usr/src/homeassistant/homeassistant/core.py", line 1673, in _execute_service
    await cast(Callable[[ServiceCall], Awaitable[None]], handler.job.target)(
  File "/usr/src/homeassistant/homeassistant/helpers/entity_component.py", line 204, in handle_service
    await self.hass.helpers.service.entity_service_call(
  File "/usr/src/homeassistant/homeassistant/helpers/service.py", line 668, in entity_service_call
    future.result()  # pop exception if have
  File "/usr/src/homeassistant/homeassistant/helpers/entity.py", line 931, in async_request_call
    await coro
  File "/usr/src/homeassistant/homeassistant/helpers/service.py", line 705, in _handle_entity_call
    await result
  File "/usr/src/homeassistant/homeassistant/components/smartthings/switch.py", line 46, in async_turn_off
    await self._device.switch_off(set_status=True)
  File "/usr/local/lib/python3.9/site-packages/pysmartthings/device.py", line 1013, in switch_off
    result = await self.command(component_id, Capability.switch, Command.off)
  File "/usr/local/lib/python3.9/site-packages/pysmartthings/device.py", line 825, in command
    response = await self._api.post_device_command(
  File "/usr/local/lib/python3.9/site-packages/pysmartthings/api.py", line 147, in post_device_command
    return await self.post(API_DEVICE_COMMAND.format(device_id=device_id), data)
  File "/usr/local/lib/python3.9/site-packages/pysmartthings/api.py", line 395, in post
    return await self.request("post", self._api_base + resource, data=data)
  File "/usr/local/lib/python3.9/site-packages/pysmartthings/api.py", line 376, in request
    resp.raise_for_status()
  File "/usr/local/lib/python3.9/site-packages/aiohttp/client_reqrep.py", line 1004, in raise_for_status
    raise ClientResponseError(
aiohttp.client_exceptions.ClientResponseError: 409, message='Conflict', url=URL('https://api.smartthings.com/v1/devices/650f9917-534d-4698-8409-29cc0a350971/commands')
2022-03-08 09:30:10 WARNING (Recorder) [homeassistant.components.sensor.recorder] Entity sensor.pixel_6_app_rx_gb from integration mobile_app has state class total_increasing, but its state is not strictly increasing. Triggered by state 0.0902 (0.0903) with last_updated set to 2022-03-08T14:28:58.574185+00:00. Please create a bug report at https://github.com/home-assistant/core/issues?q=is%3Aopen+is%3Aissue+label%3A%22integration%3A+mobile_app%22
2022-03-08 10:07:15 ERROR (MainThread) [pylitterbot.account] Unable to retrieve your robots
2022-03-08 10:09:36 ERROR (MainThread) [homeassistant.components.hassio.handler] Client error on /core/update request Server disconnected
2022-03-08 10:09:36 ERROR (MainThread) [homeassistant.components.hassio] Failed to to call /core/update - 
